2021-01-25 14:58:46,236 - Client_Library - ERROR - HTTPSConnectionPool(host='accounts.zoho.in', port=443): Max retries exceeded with url: /oauth/v2/token?client_id=1000.I3KO784W8T31PPV25LVBISUU26L62V&client_secret=df73f8c11f314be4e3e5d34194149f17c73c3ca17a&redirect_uri=http%3A%2F%2Flocalhost%3A8000%2Fsome_path&grant_type=refresh_token&refresh_token=1000.372b1eb9b53b82c2becb3680b138801d.694c771bbb0192fa9fb8cd8def286596 (Caused by NewConnectionError('<urllib3.connection.HTTPSConnection object at 0x7f1ed64cb460>: Failed to establish a new connection: [Errno -3] Temporary failure in name resolution')); Exception Message::Error occurred for https://www.zohoapis.in/crm/v2/Leads. Error Code: 0 Response error_content: None. Error Details::['  File "/usr/lib/python3.8/threading.py", line 890, in _bootstrap\n    self._bootstrap_inner()\n', '  File "/usr/lib/python3.8/threading.py", line 932, in _bootstrap_inner\n    self.run()\n', '  File "/usr/lib/python3.8/threading.py", line 870, in run\n    self._target(*self._args, **self._kwargs)\n', '  File "/usr/lib/python3.8/socketserver.py", line 650, in process_request_thread\n    self.finish_request(request, client_address)\n', '  File "/usr/lib/python3.8/socketserver.py", line 360, in finish_request\n    self.RequestHandlerClass(request, client_address, self)\n', '  File "/usr/lib/python3.8/socketserver.py", line 720, in __init__\n    self.handle()\n', '  File "/home/abhishek/my_projects/wabot/env/lib/python3.8/site-packages/werkzeug/serving.py", line 345, in handle\n    BaseHTTPRequestHandler.handle(self)\n', '  File "/usr/lib/python3.8/http/server.py", line 427, in handle\n    self.handle_one_request()\n', '  File "/home/abhishek/my_projects/wabot/env/lib/python3.8/site-packages/werkzeug/serving.py", line 379, in handle_one_request\n    return self.run_wsgi()\n', '  File "/home/abhishek/my_projects/wabot/env/lib/python3.8/site-packages/werkzeug/serving.py", line 323, in run_wsgi\n    execute(self.server.app)\n', '  File "/home/abhishek/my_projects/wabot/env/lib/python3.8/site-packages/werkzeug/serving.py", line 312, in execute\n    application_iter = app(environ, start_response)\n', '  File "/home/abhishek/my_projects/wabot/env/lib/python3.8/site-packages/flask/app.py", line 2464, in __call__\n    return self.wsgi_app(environ, start_response)\n', '  File "/home/abhishek/my_projects/wabot/env/lib/python3.8/site-packages/flask/app.py", line 2447, in wsgi_app\n    response = self.full_dispatch_request()\n', '  File "/home/abhishek/my_projects/wabot/env/lib/python3.8/site-packages/flask/app.py", line 1950, in full_dispatch_request\n    rv = self.dispatch_request()\n', '  File "/home/abhishek/my_projects/wabot/env/lib/python3.8/site-packages/flask/app.py", line 1936, in dispatch_request\n    return self.view_functions[rule.endpoint](**req.view_args)\n', '  File "server.py", line 13, in home\n    bot.processing()\n', '  File "/home/abhishek/my_projects/wabot/whatsapp.py", line 114, in processing\n    self.createlead()\n', '  File "/home/abhishek/my_projects/wabot/whatsapp.py", line 73, in createlead\n    resp=record.create()\n', '  File "/home/abhishek/my_projects/wabot/env/lib/python3.8/site-packages/zcrmsdk/Operations.py", line 315, in create\n    return EntityAPIHandler.get_instance(self).create_record(trigger, process, lar_id)\n', '  File "/home/abhishek/my_projects/wabot/env/lib/python3.8/site-packages/zcrmsdk/Handler.py", line 90, in create_record\n    apiResponse=APIRequest(handler_ins).get_api_response()\n', '  File "/home/abhishek/my_projects/wabot/env/lib/python3.8/site-packages/zcrmsdk/Request.py", line 58, in get_api_response\n    CommonUtil.raise_exception(self.url,ex.__str__(),traceback.format_stack())\n']
